<?xml version="1.0"?>
<robot name="mark_01">

  <material name="blue">
    <color rgba="0 0 0.8 1"/>
  </material>
  <material name="black">
    <color rgba="0 0 0 1"/>
  </material>
  <material name="white">
    <color rgba="1 1 1 1"/>
  </material>


  <link name="base_link">
    <visual>
      <geometry>
        <box size="0.8 0.4 0.3"/>
      </geometry>
      <material name="blue"/>
    </visual>
  </link>

  <link name="left_front_wheel">
    <visual>
      <geometry>
        <cylinder length="0.05" radius="0.1"/>
      </geometry>
      <origin rpy="1.57 0 0" xyz="0 0 0"/>
      <material name="white"/>
    </visual>
  </link>

  <joint name="base_to_left_front_wheel" type="continuous">
    <parent link="base_link"/>
    <child link="left_front_wheel"/>
    <axis xyz="0 1 0"/>
    <origin xyz="0.3 0.225 -0.15"/>
  </joint>

<link name="left_back_wheel">
    <visual>
      <geometry>
        <cylinder length="0.1" radius="0.3"/>
      </geometry>
      <origin rpy="1.57 0 0" xyz="0 0 0"/>
      <material name="white"/>
    </visual>
  </link>

  <joint name="base_to_left_back_wheel" type="continuous">
    <parent link="base_link"/>
    <child link="left_back_wheel"/>
    <axis xyz="0 1 0"/>
    <origin xyz="-0.3 0.225 0"/>
  </joint>

<link name="right_front_wheel">
    <visual>
      <geometry>
        <cylinder length="0.05" radius="0.1"/>
      </geometry>
      <origin rpy="1.57 0 0" xyz="0 0 0"/>
      <material name="white"/>
    </visual>
  </link>

  <joint name="base_to_right_front_wheel" type="continuous">
    <parent link="base_link"/>
    <child link="right_front_wheel"/>
    <axis xyz="0 1 0"/>
    <origin xyz="0.3 -0.225 -0.15"/>
  </joint>

<link name="right_back_wheel">
    <visual>
      <geometry>
        <cylinder length="0.1" radius="0.3"/>
      </geometry>
      <origin rpy="1.57 0 0" xyz="0 0 0"/>
      <material name="white"/>
    </visual>
  </link>

  <joint name="base_to_right_back_wheel" type="continuous">
    <parent link="base_link"/>
    <child link="right_back_wheel"/>
    <axis xyz="0 1 0"/>
    <origin xyz="-0.3 -0.225 0"/>
  </joint>

<link name="right_arm_1">
    <visual>
      <geometry>
        <box size="0.4 0.05 0.05"/>
      </geometry>
      <origin rpy="0 0 0" xyz="0.175 0 0"/>
      <material name="white"/>
    </visual>
  </link>

  <joint name="base_to_right_arm_1" type="revolute">
    <parent link="base_link"/>
    <child link="right_arm_1"/>
    <axis xyz="0 0 1"/>
    <origin xyz="0.375 -0.175 0.1"/>
    <limit effort="1000.0" lower="0.0" upper="-1.57" velocity="1.0"/>
  </joint>

 <link name="left_arm_1">
    <visual>
      <geometry>
        <box size="0.4 0.05 0.05"/>
      </geometry>
      <origin rpy="0 0 0" xyz="0.175 0 0"/>
      <material name="white"/>
    </visual>
  </link>

  <joint name="base_to_left_arm_1" type="revolute">
    <parent link="base_link"/>
    <child link="left_arm_1"/>
    <axis xyz="0 0 1"/>
    <origin xyz="0.375 0.175 0.1"/>
    <limit effort="1000.0" lower="0.0" upper="1.57" velocity="1.0"/>
  </joint>

 <link name="joint_left_arm">
    <visual>
      <geometry>
        <cylinder length="0.05" radius="0.025"/>
      </geometry>
      <origin rpy="0 0 0" xyz="0 0 0"/>
      <material name="black"/>
    </visual>
  </link>

  <joint name="joint_of_left_arm" type="revolute">
    <parent link="left_arm_1"/>
    <child link="joint_left_arm"/>
    <axis xyz="0 0 1"/>
    <origin xyz="0.375 0 0"/>
    <limit effort="1000.0" lower="0.0" upper="-1.57" velocity="1.0"/>
  </joint>

 <link name="left_arm_2">
    <visual>
      <geometry>
        <box size="0.4 0.05 0.05"/>
      </geometry>
      <origin rpy="0 0 0" xyz="0.175 0 0"/>
      <material name="white"/>
    </visual>
  </link>

<joint name="wrist_of_left_arm" type="fixed">
    <parent link="joint_left_arm"/>
    <child link="left_arm_2"/>
  </joint>

<link name="joint_right_arm">
    <visual>
      <geometry>
        <cylinder length="0.05" radius="0.025"/>
      </geometry>
      <origin rpy="0 0 0" xyz="0 0 0"/>
      <material name="black"/>
    </visual>
  </link>

  <joint name="joint_of_right_arm" type="revolute">
    <parent link="right_arm_1"/>
    <child link="joint_right_arm"/>
    <axis xyz="0 0 1"/>
    <origin xyz="0.375 0 0"/>
    <limit effort="1000.0" lower="0.0" upper="1.57" velocity="1.0"/>
  </joint>

 <link name="right_arm_2">
    <visual>
      <geometry>
        <box size="0.4 0.05 0.05"/>
      </geometry>
      <origin rpy="0 0 0" xyz="0.175 0 0"/>
      <material name="white"/>
    </visual>
  </link>

<joint name="wrist_of_right_arm" type="fixed">
    <parent link="joint_right_arm"/>
    <child link="right_arm_2"/>
  </joint>
</robot>
